<?xml version="1.0"?>
<robot xmlns:xacro="http://ros.org/wiki/xacro">
  
  <!-- COLOR -->
  <material name="white"> <color rgba="1 1 1 1" /> </material>
  <material name="black"> <color rgba="0 0 0 1" /> </material>
  <material name="blue">  <color rgba="0 0 1 1"/>  </material>
  
  <!-- Define robot constants -->
  <xacro:property name="base_width" value="0.3"/>
  <xacro:property name="base_length" value="0.24"/>
  <xacro:property name="base_height" value="0.05"/>
  <xacro:property name="base_zoff" value="0.105"/>
  
  <xacro:property name="wheel_radius" value="0.0435"/>
  <xacro:property name="wheel_width" value="0.04"/>
  <xacro:property name="wheel_ygap" value="0.025"/>
  <xacro:property name="wheel_zoff" value="0.0615"/>
  <xacro:property name="wheel_xoff" value="0.07"/>

  <xacro:property name="caster_xoff" value="0.1"/>

  <!-- Define some commonly used intertial properties  -->
  <!-- reference from nav2 urdf document  -->
  <xacro:macro name="box_inertia" params="m w h d">
    <inertial>
      <origin xyz="0 0 0" rpy="${pi/2} 0 ${pi/2}"/>
      <mass value="${m}"/>
      <inertia ixx="${(m/12) * (h*h + d*d)}" ixy="0.0" ixz="0.0" iyy="${(m/12) * (w*w + d*d)}" iyz="0.0" izz="${(m/12) * (w*w + h*h)}"/>
    </inertial>
  </xacro:macro>

  <xacro:macro name="cylinder_inertia" params="m r h">
    <inertial>
      <origin xyz="0 0 0" rpy="${pi/2} 0 0" />
      <mass value="${m}"/>
      <inertia ixx="${(m/12) * (3*r*r + h*h)}" ixy = "0.0" ixz = "0.0" iyy="${(m/12) * (3*r*r + h*h)}" iyz = "0.0" izz="${(m/2) * (r*r)}"/>
    </inertial>
  </xacro:macro>

  <xacro:macro name="sphere_inertia" params="m r">
    <inertial>
      <mass value="${m}"/>
      <inertia ixx="${(2/5) * m * (r*r)}" ixy="0.0" ixz="0.0" iyy="${(2/5) * m * (r*r)}" iyz="0.0" izz="${(2/5) * m * (r*r)}"/>
    </inertial>
  </xacro:macro>

  <!-- Robot Base -->
  <link name="base_link">

  </link>

  <!-- Robot Footprint -->
  <link name="base_footprint">
  </link>

  <joint name="base_footprint_joint" type="fixed">
    <parent link="base_link"/>
    <child link="base_footprint"/>
    <origin xyz="0.0 0.0 0.0" rpy="0 0 0"/>
  </joint>

  <!-- body link -->
  <link name="body_link">
    <visual>
        <geometry>
          <box size="${base_length} ${base_width} ${base_height}"/>
        </geometry>
        <material name="white"/>
    </visual>
  
    <collision>
      <geometry>
        <box size="${base_length} ${base_width} ${base_height}"/>
      </geometry>
    </collision>
  
    <xacro:box_inertia m="15" w="${base_width}" d="${base_length}" h="${base_height}"/>
  </link>

  <joint name="body_link_joint" type="fixed">
    <parent link="base_link"/>
    <child link="body_link"/>
    <origin xyz="0.0 0.0 ${base_zoff}" rpy="0 0 0"/>
  </joint>

  <gazebo reference="base_link"><material>Gazebo/White</material></gazebo>

  <!-- Wheels -->
  <xacro:macro name="wheel" params="prefix x_reflect y_reflect">
    <link name="${prefix}_link">
      <visual>
        <origin xyz="0 0 0" rpy="${pi/2} 0 0"/>
        <geometry>
          <cylinder radius="${wheel_radius}" length="${wheel_width}"/>
        </geometry>
        <material name="black"/>
      </visual>

      <collision>
        <origin xyz="0 0 0" rpy="${pi/2} 0 0"/>
        <geometry>
          <sphere radius="${wheel_radius}"/>
        </geometry>
      </collision>

      <xacro:cylinder_inertia m="0.5" r="${wheel_radius}" h="${wheel_width}"/>
    </link>

    <joint name="${prefix}_joint" type="continuous">
      <parent link="body_link"/>
      <child link="${prefix}_link"/>
      <origin xyz="${x_reflect*wheel_xoff} ${y_reflect*(base_width/2+wheel_ygap)} ${-wheel_zoff}" rpy="0 0 0"/>
      <axis xyz="0 1 0"/>
    </joint>
  </xacro:macro>

  <xacro:wheel prefix="left_wheel" x_reflect="-1" y_reflect="1" />
  <xacro:wheel prefix="right_wheel" x_reflect="-1" y_reflect="-1" />
  <gazebo reference="left_wheel_link"><material>Gazebo/Black</material></gazebo>
  <gazebo reference="right_wheel_link"><material>Gazebo/Black</material></gazebo>

  <!-- caster -->
  <link name="front_caster_link">
    <visual>
      <geometry>
        <sphere radius="${wheel_radius}"/>
      </geometry>
      <material name="white"/>
    </visual>

    <collision>
      <origin xyz="0 0 0" rpy="0 0 0"/>
      <geometry>
        <sphere radius="${wheel_radius}"/>
      </geometry>
    </collision>

    <xacro:sphere_inertia m="0.5" r="${wheel_radius}"/>
  </link>

  <joint name="caster_joint" type="fixed">
    <parent link="body_link"/>
    <child link="front_caster_link"/>
    <origin xyz="${caster_xoff} 0.0 ${(-wheel_zoff)}" rpy="0 0 0"/>
  </joint>

  <gazebo reference="front_caster_link">
        <material>Gazebo/White</material>
        <mu1 value="0.001"/>
        <mu2 value="0.001"/>
  </gazebo>


</robot>